<!-- 
6.3.3 URDF语法详解03_joint
    joint
    urdf 中的 joint 标签用于描述机器人关节的运动学和动力学属性，还可以指定关节运动的安全极限，
    机器人的两个部件(分别称之为 parent link 与 child link)以"关节"的形式相连接，不同的关节有不同的运动形式: 
    旋转、滑动、固定、旋转速度、旋转角度限制....,比如:安装在底座上的轮子可以360度旋转，而摄像头则可能是完全固定在底座上。

    joint标签对应的数据在模型中是不可见的
 -->

<robot name="mycar">
<!--需求：设置机器人底盘，并添加摄像头-->
<!--底盘link-->
<link name="base_link">
    <visual>
       <geometry>
          <box size="0.3 0.2 0.1"/>
       </geometry>
       <origin xyz="0 0 0" rpy="0 0 0"/>
       <material name="car_color">
           <color rgba="0.7 0.8 0 1"/>
       </material>
    </visual>
</link>

<!--摄像头link-->
<link name="camera">
    <visual>
       <geometry>
          <box size="0.03 0.05 0.05"/>
       </geometry>
       <!--先使用默认（后期需要修改）-->
       <origin xyz="0 0 0.025" rpy="0 0 0"/>
       <material name="camera_color">
           <color rgba="0 0 1 1"/>
       </material>
    </visual>
</link>

<!--关节-->
<joint name="camera2base" type="continuous">
     <!--父级link-->
     <parent link="base_link"/>
     <!--子级link-->
     <child link="camera"/>
     <!--设置偏移量-->
     <origin xyz="0.12 0 0.05" rpy="0 0 0"/>
     <!--设置关节旋转参考的坐标系-->
     <axis xyz="0 0 1"/>
</joint>
  
</robot>